Workbook

Sheet Draft Plan (You @ 3)
A1: 2026 FANTASY DRAFT CHEAT SHEET — Pick #3, Snake
A2: VERIFIED FROM SLEEPER — "GovSmart Gridiron": 12-team snake • 0.5 PPR • 6-PT passing TDs • $100 FAAB • your slot #3 • draft Fri Sep 4, 5:30 PM ET, 90s pick timer. ROSTER: QB / RB / RB / WR / WR / TE / FLEX / DEF + 4 BENCH — only 12 rounds, NO KICKER, and a DEFENSE is a required starter. 2 IR slots let you stash an injured guy. 6-pt pass TDs lift EVERY QB including the streamer, so the elite QB's edge grows only 7-19 pts ALL SEASON (measured across 2024+2025) — WAIT ON QB until round 9+, then take the highest PASSING-TD volume left (the rule pays 2 pts per passing TD and nothing for rushing).
A3: YOUR 12 PICKS (slot 3, snake): R1 #3 • R2 #22 • R3 #27 • R4 #46 • R5 #51 • R6 #70 • R7 #75 • R8 #94 • R9 #99 • R10 #118 • R11 #123 • R12 #142 — that's the whole draft.
A5: Rd | B5: Your Pick | C5: On Board (ADP) | D5: BEST TARGET (take one) | E5: Fallbacks / Best Available | F5: Plan
A6: 1 | B6: 3 | C6: 1-6 | D6: Ja'Marr Chase or Puka Nacua (elite WR1) | E6: Jaxon Smith-Njigba; Bijan Robinson if he slips | F6: Gibbs & Bijan usually gone 1-2. Lock an elite WR. Don't overthink it.
A7: 2 | B7: 22 | C7: 18-25 | D7: Kenneth Walker III or Omarion Hampton (anchor an RB) | E7: Ashton Jeanty if he slides (ankle discount); Nico Collins / A.J. Brown (WR) | F7: RB dries up fast. Grab your RB1 at the turn.
A8: 3 | B8: 27 | C8: 24-31 | D8: Malik Nabers or Zay Flowers (WR); Kyren Williams (RB) | E8: Chris Olave; Jeremiyah Love; DeVonta Smith | F8: You pick 22 & 27 back-to-back. Take whichever position you skipped at 22.
A9: 4 | B9: 46 | C9: 43-52 | D9: Brock Bowers (elite-TE edge) OR Terry McLaurin / DJ Moore (WR) | E9: Bucky Irving; Quinshon Judkins (RB) | F9: Only 12 rounds — Bowers here locks TE and frees every later pick.
A10: 5 | B10: 51 | C10: 48-58 | D10: RB Quinshon Judkins or WR Mike Evans — keep stacking starters | E10: Bucky Irving; Rome Odunze; Jaylen Waddle | F10: Do NOT take a QB here. Top QB is worth ~60 pts over replacement; a top RB is worth ~227.
A11: 6 | B11: 70 | C11: 60-72 | D11: DK Metcalf / Marvin Harrison Jr. (WR upside) | E11: TreVeyon Henderson (RB); Christian Watson | F11: Fill your last open starting WR or RB here. Still not QB.
A12: 7 | B12: 75 | C12: 72-80 | D12: Jordan Addison / Jayden Reed (WR) | E12: Tony Pollard (RB); a starting TE if you still need one | F12: Bench is only 4 deep — starters beat lottery tickets.
A13: 8 | B13: 94 | C13: 87-99 | D13: Finish your 7 offensive starters — best WR/RB/TE left | E13: Tyler Warren / Kyle Pitts (TE); Matthew Golden (WR) | F13: Every starter filled before you spend a pick on QB.
A14: 9 | B14: 99 | C14: 94-104 | D14: QB NOW — Stafford / Prescott / Herbert / Lawrence / Mahomes | E14: Best FLEX left if two QBs you like are still there | F14: The QB window. 2025: Stafford +92 pts from the 6-pt rule vs Allen +50, at 56 picks cheaper.
A15: 10 | B15: 118 | C15: 110-123 | D15: Handcuff your RB1/RB2 (RJ Harvey, Jonathon Brooks) | E15: Kyle Pitts (TE2); Justin Herbert / Bo Nix (QB2) | F15: Only 4 bench spots — protect the studs you already paid for.
A16: 11 | B16: 123 | C16: Best avail. | D16: Best upside swing left on the board | E16: 2nd TE or QB if you're thin there | F16: Last real value pick. Ceiling over floor.
A17: 12 | B17: 142 | C17: Last pick | D17: DEFENSE — Seattle / Denver / Houston (best Week-1 matchup) | E17: — | F17: NO KICKER in this league. DEF is a required starter — this is the pick for it.
A19: TURN SCENARIOS — PICKS 22 & 27 (you pick back-to-back)
A20: DEFAULT (you took a WR at 3): leave the 22/27 turn with an RB anchor + one more stud. Ideal pairs: Walker + Nabers · Hampton + Kyren · Jacobs + Olave.
A21: CHASE AND NACUA BOTH GONE AT 3: take Jaxon Smith-Njigba. Do NOT reach for an RB at 3 — the Tier-1 WR still wins the pick.
A22: GIBBS OR BIJAN SLIDES TO 3: take him. Then go WR + WR at 22/27 (A.J. Brown / Nico + Nabers / Flowers) — your RB1 is already banked.
A23: JEANTY FALLS TO 22: ankle discount, not a red flag — and you have 2 IR slots, so a slow start is survivable. Otherwise Walker is the safe anchor.
A24: ROSTER SHAPE: 12 rounds, 8 starters (QB/RB/RB/WR/WR/TE/FLEX/DEF), 4 bench, NO KICKER. Every pick is a roster spot — there is no room for dead weight.
A25: QB, MEASURED (nflverse 2024+2025, re-scored to 6-pt): the rule lifts the STREAMER too, so a top-6 QB's ADVANTAGE grows only 7-19 pts across a WHOLE SEASON (median 12.5 over 2 seasons x 3 replacement ranks). The single best QB is much noisier (-4 to +34) and not worth planning around. The real reason to wait is value over replacement: best QB ~53 pts, best TE ~113, best WR ~117, best RB ~228. The rule pays exactly 2 pts per PASSING TD and nothing extra for rushing, so judge a QB on passing-TD volume. Wait until round 9.

Sheet Big Board
A1: BIG BOARD — 2026 Half-PPR (Top 129)
A2: Drafted? (col I): x for EVERY pick by anyone — greys the row out. MINE? (col J): x for YOUR picks — turns green and feeds the Live Tracker tab. ADP = live 12-team half-PPR market thru ~#60 (refreshed Aug 27); 61+ = expert consensus. QBs carry a 6-pt pass-TD bump.
A4: Rank | B4: Tier | C4: Player | D4: Pos | E4: Team | F4: Bye | G4: ADP | H4: Notes | I4: Drafted? | J4: MINE?
A5: 1 | B5: T1 | C5: Jahmyr Gibbs | D5: RB | E5: DET | F5: 6 | G5: 1.5
A6: 2 | B6: T1 | C6: Bijan Robinson | D6: RB | E6: ATL | F6: 11 | G6: 2.2
A7: 3 | B7: T1 | C7: Puka Nacua | D7: WR | E7: LAR | F7: 11 | G7: 3.0 | H7: Groin — minor, expected Wk1
A8: 4 | B8: T1 | C8: Ja'Marr Chase | D8: WR | E8: CIN | F8: 6 | G8: 3.9 | H8: Safest WR1
A9: 5 | B9: T1 | C9: Jaxon Smith-Njigba | D9: WR | E9: SEA | F9: 11 | G9: 5.2
A10: 6 | B10: T2 | C10: Jonathan Taylor | D10: RB | E10: IND | F10: 13 | G10: 5.9
A11: 7 | B11: T2 | C11: Christian McCaffrey | D11: RB | E11: SF | F11: 8 | G11: 6.6 | H11: Elite when healthy
A12: 8 | B12: T2 | C12: Amon-Ra St. Brown | D12: WR | E12: DET | F12: 6 | G12: 8.0
A13: 9 | B13: T2 | C13: James Cook III | D13: RB | E13: BUF | F13: 7 | G13: 9.3
A14: 10 | B14: T2 | C14: Derrick Henry | D14: RB | E14: BAL | F14: 13 | G14: 9.7 | H14: Age, still elite
A15: 11 | B15: T2 | C15: De'Von Achane | D15: RB | E15: MIA | F15: 6 | G15: 11.7
A16: 12 | B16: T2 | C16: Drake London | D16: WR | E16: ATL | F16: 11 | G16: 12.0
A17: 13 | B17: T2 | C17: CeeDee Lamb | D17: WR | E17: DAL | F17: 14 | G17: 12.5
A18: 14 | B18: T3 | C18: Justin Jefferson | D18: WR | E18: MIN | F18: 6 | G18: 14.4
A19: 15 | B19: T3 | C19: Chase Brown | D19: RB | E19: CIN | F19: 6 | G19: 15.1
A20: 16 | B20: T3 | C20: Rashee Rice | D20: WR | E20: KC | F20: 5 | G20: 15.2
A21: 17 | B21: T3 | C21: Saquon Barkley | D21: RB | E21: PHI | F21: 10 | G21: 17.6
A22: 18 | B22: T3 | C22: Nico Collins | D22: WR | E22: HOU | F22: 8 | G22: 18.4
A23: 19 | B23: T3 | C23: Ashton Jeanty | D23: RB | E23: LV | F23: 13 | G23: 18.9 | H23: Ankle — Wk1 uncertain; ADP sliding (~15 to 19)
A24: 20 | B24: T3 | C24: George Pickens | D24: WR | E24: DAL | F24: 14 | G24: 19.9
A25: 21 | B25: T3 | C25: A.J. Brown | D25: WR | E25: NE | F25: 11 | G25: 20.0 | H25: New team (NE)
A26: 22 | B26: T3 | C26: Kenneth Walker III | D26: RB | E26: KC | F26: 5 | G26: 20.5 | H26: Now in KC
A27: 23 | B27: T4 | C27: Chris Olave | D27: WR | E27: NO | F27: 8 | G27: 23.2
A28: 24 | B28: T4 | C28: Omarion Hampton | D28: RB | E28: LAC | F28: 7 | G28: 24.0
A29: 25 | B29: T4 | C29: Zay Flowers | D29: WR | E29: BAL | F29: 13 | G29: 25.2
A30: 26 | B30: T4 | C30: Josh Jacobs | D30: RB | E30: GB | F30: 11 | G30: 25.4
A31: 27 | B31: T4 | C31: Malik Nabers | D31: WR | E31: NYG | F31: 8 | G31: 26.2 | H31: Knee — expected Wk1
A32: 28 | B32: T4 | C32: Kyren Williams | D32: RB | E32: LAR | F32: 11 | G32: 27.4
A33: 29 | B33: T4 | C33: Jeremiyah Love | D33: RB | E33: ARI | F33: 14 | G33: 29.0 | H33: Rookie; high-ankle — expected Wk1
A34: 30 | B34: T4 | C34: Tetairoa McMillan | D34: WR | E34: CAR | F34: 5 | G34: 30.7
A35: 31 | B35: T4 | C35: Garrett Wilson | D35: WR | E35: NYJ | F35: 13 | G35: 31.1
A36: 32 | B36: T4 | C36: DeVonta Smith | D36: WR | E36: PHI | F36: 10 | G36: 31.6 | H36: Value
A37: 33 | B37: T5 | C37: Josh Allen | D37: QB | E37: BUF | F37: 7 | G37: 33.0 | H37: QB1 overall — 6-pt pass-TD riser
A38: 34 | B38: T5 | C38: Javonte Williams | D38: RB | E38: DAL | F38: 14 | G38: 33.2 | H38: Now in DAL
A39: 35 | B39: T5 | C39: Breece Hall | D39: RB | E39: NYJ | F39: 13 | G39: 33.5 | H39: Groin — expected Wk1; market rising
A40: 36 | B40: T5 | C40: Emeka Egbuka | D40: WR | E40: TB | F40: 10 | G40: 33.7 | H40: Toe — monitor (Q)
A41: 37 | B41: T5 | C41: Tee Higgins | D41: WR | E41: CIN | F41: 6 | G41: 35.9
...

Sheet Live Tracker
A1: LIVE DRAFT TRACKER — computes as you mark the Big Board
A2: During the draft: on the Big Board put x in Drafted? (col I) for EVERY pick made by anyone, and ALSO x in MINE? (col J) for your own picks. 12 rounds, no kicker, DEF required in R12.
B4: QB | C4: RB | D4: WR | E4: TE
A5: My roster count | B5: =COUNTIFS('Big Board'!$D$5:$D$133,B$4,'Big Board'!$J$5:$J$133,"x") | C5: =COUNTIFS('Big Board'!$D$5:$D$133,C$4,'Big Board'!$J$5:$J$133,"x") | D5: =COUNTIFS('Big Board'!$D$5:$D$133,D$4,'Big Board'!$J$5:$J$133,"x") | E5: =COUNTIFS('Big Board'!$D$5:$D$133,E$4,'Big Board'!$J$5:$J$133,"x")
A6: Starters still needed | B6: =MAX(0,1-B5) | C6: =MAX(0,2-C5) | D6: =MAX(0,2-D5) | E6: =MAX(0,1-E5) | F6: (+1 FLEX, +1 DEF in R12 — no kicker)
A7: Top-tier left (undrafted) | B7: =COUNTIFS('Big Board'!$D$5:$D$133,B$4,'Big Board'!$B$5:$B$133,"T5",'Big Board'!$I$5:$I$133,"<>x")+COUNTIFS('Big Board'!$D$5:$D$133,B$4,'Big Board'!$B$5:$B$133,"T6",'Big Board'!$I$5:$I$133,"<>x") | C7: =COUNTIFS('Big Board'!$D$5:$D$133,C$4,'Big Board'!$B$5:$B$133,"T1",'Big Board'!$I$5:$I$133,"<>x")+COUNTIFS('Big Board'!$D$5:$D$133,C$4,'Big Board'!$B$5:$B$133,"T2",'Big Board'!$I$5:$I$133,"<>x") | D7: =COUNTIFS('Big Board'!$D$5:$D$133,D$4,'Big Board'!$B$5:$B$133,"T1",'Big Board'!$I$5:$I$133,"<>x")+COUNTIFS('Big Board'!$D$5:$D$133,D$4,'Big Board'!$B$5:$B$133,"T2",'Big Board'!$I$5:$I$133,"<>x") | E7: =COUNTIFS('Big Board'!$D$5:$D$133,E$4,'Big Board'!$B$5:$B$133,"T5",'Big Board'!$I$5:$I$133,"<>x")+COUNTIFS('Big Board'!$D$5:$D$133,E$4,'Big Board'!$B$5:$B$133,"T6",'Big Board'!$I$5:$I$133,"<>x")
A8: Next tier left | B8: =COUNTIFS('Big Board'!$D$5:$D$133,B$4,'Big Board'!$B$5:$B$133,"T7",'Big Board'!$I$5:$I$133,"<>x")+COUNTIFS('Big Board'!$D$5:$D$133,B$4,'Big Board'!$B$5:$B$133,"T8",'Big Board'!$I$5:$I$133,"<>x") | C8: =COUNTIFS('Big Board'!$D$5:$D$133,C$4,'Big Board'!$B$5:$B$133,"T3",'Big Board'!$I$5:$I$133,"<>x")+COUNTIFS('Big Board'!$D$5:$D$133,C$4,'Big Board'!$B$5:$B$133,"T4",'Big Board'!$I$5:$I$133,"<>x") | D8: =COUNTIFS('Big Board'!$D$5:$D$133,D$4,'Big Board'!$B$5:$B$133,"T3",'Big Board'!$I$5:$I$133,"<>x")+COUNTIFS('Big Board'!$D$5:$D$133,D$4,'Big Board'!$B$5:$B$133,"T4",'Big Board'!$I$5:$I$133,"<>x") | E8: =COUNTIFS('Big Board'!$D$5:$D$133,E$4,'Big Board'!$B$5:$B$133,"T8",'Big Board'!$I$5:$I$133,"<>x")+COUNTIFS('Big Board'!$D$5:$D$133,E$4,'Big Board'!$B$5:$B$133,"T9",'Big Board'!$I$5:$I$133,"<>x")
A10: My bye weeks: | B10: 5 | C10: 6 | D10: 7 | E10: 8 | F10: 9 | G10: 10 | H10: 11 | I10: 13 | J10: 14
A11: Count (3+ same bye = fix it) | B11: =COUNTIFS('Big Board'!$F$5:$F$133,B$10,'Big Board'!$J$5:$J$133,"x") | C11: =COUNTIFS('Big Board'!$F$5:$F$133,C$10,'Big Board'!$J$5:$J$133,"x") | D11: =COUNTIFS('Big Board'!$F$5:$F$133,D$10,'Big Board'!$J$5:$J$133,"x") | E11: =COUNTIFS('Big Board'!$F$5:$F$133,E$10,'Big Board'!$J$5:$J$133,"x") | F11: =COUNTIFS('Big Board'!$F$5:$F$133,F$10,'Big Board'!$J$5:$J$133,"x") | G11: =COUNTIFS('Big Board'!$F$5:$F$133,G$10,'Big Board'!$J$5:$J$133,"x") | H11: =COUNTIFS('Big Board'!$F$5:$F$133,H$10,'Big Board'!$J$5:$J$133,"x") | I11: =COUNTIFS('Big Board'!$F$5:$F$133,I$10,'Big Board'!$J$5:$J$133,"x") | J11: =COUNTIFS('Big Board'!$F$5:$F$133,J$10,'Big Board'!$J$5:$J$133,"x")
A13: SNAKE PICK CALCULATOR
A14: Teams: | B14: 12
A15: Your slot: | B15: 3
A16: (yellow cells are inputs — picks below recompute if league changes)
A17: Round | B17: Overall pick
A18: 1 | B18: =IF(MOD(A18,2)=1,$B$14*(A18-1)+$B$15,$B$14*A18-$B$15+1)
A19: 2 | B19: =IF(MOD(A19,2)=1,$B$14*(A19-1)+$B$15,$B$14*A19-$B$15+1)
A20: 3 | B20: =IF(MOD(A20,2)=1,$B$14*(A20-1)+$B$15,$B$14*A20-$B$15+1)
A21: 4 | B21: =IF(MOD(A21,2)=1,$B$14*(A21-1)+$B$15,$B$14*A21-$B$15+1)
A22: 5 | B22: =IF(MOD(A22,2)=1,$B$14*(A22-1)+$B$15,$B$14*A22-$B$15+1)
A23: 6 | B23: =IF(MOD(A23,2)=1,$B$14*(A23-1)+$B$15,$B$14*A23-$B$15+1)
A24: 7 | B24: =IF(MOD(A24,2)=1,$B$14*(A24-1)+$B$15,$B$14*A24-$B$15+1)
A25: 8 | B25: =IF(MOD(A25,2)=1,$B$14*(A25-1)+$B$15,$B$14*A25-$B$15+1)
A26: 9 | B26: =IF(MOD(A26,2)=1,$B$14*(A26-1)+$B$15,$B$14*A26-$B$15+1)
A27: 10 | B27: =IF(MOD(A27,2)=1,$B$14*(A27-1)+$B$15,$B$14*A27-$B$15+1)
A28: 11 | B28: =IF(MOD(A28,2)=1,$B$14*(A28-1)+$B$15,$B$14*A28-$B$15+1)
A29: 12 | B29: =IF(MOD(A29,2)=1,$B$14*(A29-1)+$B$15,$B$14*A29-$B$15+1)

Sheet By Position
A1: RUNNING BACKS | F1: WIDE RECEIVERS | K1: QUARTERBACKS | P1: TIGHT ENDS | U1: ADP '-' = expert-rank tier (beyond live top-60 ADP)
A2: Tier | B2: Player | C2: Tm | D2: ADP | F2: Tier | G2: Player | H2: Tm | I2: ADP | K2: Tier | L2: Player | M2: Tm | N2: ADP | P2: Tier | Q2: Player | R2: Tm | S2: ADP
A3: T1 | B3: Jahmyr Gibbs | C3: DET | D3: 1.5 | F3: T1 | G3: Puka Nacua | H3: LAR | I3: 3.0 | K3: T5 | L3: Josh Allen | M3: BUF | N3: 33.0 | P3: T5 | Q3: Trey McBride | R3: ARI | S3: 37.8
A4: T1 | B4: Bijan Robinson | C4: ATL | D4: 2.2 | F4: T1 | G4: Ja'Marr Chase | H4: CIN | I4: 3.9 | K4: T6 | L4: Drake Maye | M4: NE | N4: 51.3 | P4: T6 | Q4: Brock Bowers | R4: LV | S4: 44.0
A5: T2 | B5: Jonathan Taylor | C5: IND | D5: 5.9 | F5: T1 | G5: J. Smith-Njigba | H5: SEA | I5: 5.2 | K5: T6 | L5: Lamar Jackson | M5: BAL | N5: 55.5 | P5: T8 | Q5: George Kittle | R5: SF | S5: -
A6: T2 | B6: C. McCaffrey | C6: SF | D6: 6.6 | F6: T2 | G6: Amon-Ra St. Brown | H6: DET | I6: 8.0 | K6: T7 | L6: Joe Burrow | M6: CIN | N6: 57.5 | P6: T9 | Q6: Colston Loveland | R6: CHI | S6: -
A7: T2 | B7: James Cook III | C7: BUF | D7: 9.3 | F7: T2 | G7: Drake London | H7: ATL | I7: 12.0 | K7: T8 | L7: Dak Prescott | M7: DAL | N7: - | P7: T9 | Q7: Tyler Warren | R7: IND | S7: -
A8: T2 | B8: Derrick Henry | C8: BAL | D8: 9.7 | F8: T2 | G8: CeeDee Lamb | H8: DAL | I8: 12.5 | K8: T8 | L8: Jayden Daniels | M8: WAS | N8: - | P8: T9 | Q8: Harold Fannin Jr. | R8: CLE | S8: -
A9: T2 | B9: De'Von Achane | C9: MIA | D9: 11.7 | F9: T3 | G9: Justin Jefferson | H9: MIN | I9: 14.4 | K9: T8 | L9: Matthew Stafford | M9: LAR | N9: - | P9: T10 | Q9: Kyle Pitts Sr. | R9: ATL | S9: -
A10: T3 | B10: Chase Brown | C10: CIN | D10: 15.1 | F10: T3 | G10: Rashee Rice | H10: KC | I10: 15.2 | K10: T9 | L10: Jalen Hurts | M10: PHI | N10: - | P10: T10 | Q10: Dallas Goedert | R10: PHI | S10: -
A11: T3 | B11: Saquon Barkley | C11: PHI | D11: 17.6 | F11: T3 | G11: Nico Collins | H11: HOU | I11: 18.4 | K11: T9 | L11: Brock Purdy | M11: SF | N11: -
A12: T3 | B12: Ashton Jeanty | C12: LV | D12: 18.9 | F12: T3 | G12: George Pickens | H12: DAL | I12: 19.9 | K12: T9 | L12: Trevor Lawrence | M12: JAX | N12: -
A13: T3 | B13: Kenneth Walker III | C13: KC | D13: 20.5 | F13: T3 | G13: A.J. Brown | H13: NE | I13: 20.0 | K13: T9 | L13: Caleb Williams | M13: CHI | N13: -
A14: T4 | B14: Omarion Hampton | C14: LAC | D14: 24.0 | F14: T4 | G14: Chris Olave | H14: NO | I14: 23.2 | K14: T9 | L14: Jared Goff | M14: DET | N14: -
A15: T4 | B15: Josh Jacobs | C15: GB | D15: 25.4 | F15: T4 | G15: Zay Flowers | H15: BAL | I15: 25.2 | K15: T9 | L15: Patrick Mahomes | M15: KC | N15: -
A16: T4 | B16: Kyren Williams | C16: LAR | D16: 27.4 | F16: T4 | G16: Malik Nabers | H16: NYG | I16: 26.2 | K16: T10 | L16: Justin Herbert | M16: LAC | N16: -
A17: T4 | B17: Jeremiyah Love | C17: ARI | D17: 29.0 | F17: T4 | G17: Tetairoa McMillan | H17: CAR | I17: 30.7 | K17: T10 | L17: Bo Nix | M17: DEN | N17: -
A18: T5 | B18: Javonte Williams | C18: DAL | D18: 33.2 | F18: T4 | G18: Garrett Wilson | H18: NYJ | I18: 31.1 | K18: T10 | L18: Jaxson Dart | M18: NYG | N18: -
A19: T5 | B19: Breece Hall | C19: NYJ | D19: 33.5 | F19: T4 | G19: DeVonta Smith | H19: PHI | I19: 31.6
A20: T5 | B20: Travis Etienne Jr. | C20: NO | D20: 37.3 | F20: T5 | G20: Emeka Egbuka | H20: TB | I20: 33.7 | K20: 6-PT PASS TDs — WHAT THE DATA ACTUALLY SAYS: the rule lifts every QB, streamer included, so the elite QB's edge over a streamer grows only 7-19 pts across a WHOLE season (median 12.5, measured over 2024+2025 x 3 replacement ranks). The rule pays exactly 2 pts per PASSING TD and nothing extra for rushing, so judge on passing-TD volume — 2025: Stafford +92, Goff +68, Maye +62; 2024: Burrow +86, Mayfield +82, Jackson +82. Wait on QB until round 9. Source: build_edge.py on nflverse.
A21: T5 | B21: Cam Skattebo | C21: NYG | D21: 38.4 | F21: T5 | G21: Tee Higgins | H21: CIN | I21: 35.9
A22: T6 | B22: D'Andre Swift | C22: CHI | D22: 43.2 | F22: T5 | G22: Davante Adams | H22: LAR | I22: 37.9
A23: T6 | B23: Bucky Irving | C23: TB | D23: 47.0 | F23: T5 | G23: Jameson Williams | H23: DET | I23: 38.7
A24: T6 | B24: Quinshon Judkins | C24: CLE | D24: 51.5 | F24: T5 | G24: Ladd McConkey | H24: LAC | I24: 41.0
A25: T6 | B25: Bhayshul Tuten | C25: JAX | D25: 52.5 | F25: T6 | G25: DJ Moore | H25: BUF | I25: 44.9
A26: T6 | B26: David Montgomery | C26: HOU | D26: 55.5 | F26: T6 | G26: Terry McLaurin | H26: WAS | I26: 45.1
A27: T7 | B27: Ollie Gordon II | C27: MIA | D27: - | F27: T6 | G27: Jaylen Waddle | H27: DEN | I27: 47.3
A28: T7 | B28: Jaylen Warren | C28: PIT | D28: - | F28: T6 | G28: Rome Odunze | H28: CHI | I28: 48.9
A29: T7 | B29: R. Stevenson | C29: NE | D29: - | F29: T6 | G29: Mike Evans | H29: SF | I29: 54.2
A30: T7 | B30: TreVeyon Henderson | C30: NE | D30: - | F30: T7 | G30: Christian Watson | H30: GB | I30: 56.0
A31: T8 | B31: Tony Pollard | C31: TEN | D31: - | F31: T7 | G31: Luther Burden III | H31: CHI | I31: 57.6
A32: T8 | B32: Rico Dowdle | C32: PIT | D32: - | F32: T7 | G32: Courtland Sutton | H32: DEN | I32: 59.1
... A37: T10 | B37: Kenny Gainwell | C37: TB | D37: - | F37: T8 | G37: Jordan Addison | H37: MIN | I37: -
F38: T8 | G38: Jayden Reed | H38: GB | I38: -
F39: T8 | G39: Xavier Worthy | H39: KC | I39: -
F40: T9 | G40: Matthew Golden | H40: GB | I40: -
F41: T9 | G41: Khalil Shakir | H41: BUF | I41: -
F42: T9 | G42: Makai Lemon | H42: PHI | I42: -

Sheet Sleepers • Values • Fades
A1: SLEEPERS • VALUES • FADES • INJURY WATCH
A3: VALUES (talent > draft cost — target these)
A4: DeVonta Smith (WR, PHI) | B4: Locked-in WR2 going as a WR3.
A5: Breece Hall (RB, NYJ) | B5: Groin now, but RB1 talent at an RB2 price — buy the dip if healthy.
A6: Jameson Williams (WR, DET) | B6: Big-play ceiling in a loaded offense.
A7: TreVeyon Henderson (RB, NE) | B7: Explosive; can seize the NE backfield.
A8: Matthew Stafford / Dak Prescott (QB) | B8: 46 and 30 pass TDs in 2025 = +92 and +60 pts from the 6-pt rule, going 50+ picks after Allen. Judge QBs on passing-TD volume, not rushing reputation.
A9: Marvin Harrison Jr. (WR, ARI) | B9: Year-3 bounce-back at a discount.
A11: SLEEPERS (late-round upside swings)
A12: Makai Lemon (WR, PHI) | B12: Rookie with real target path.
A13: Carnell Tate (WR, TEN) | B13: Rookie; volume if he wins the role.
A14: Matthew Golden (WR, GB) | B14: Ascending role in GB.
A15: Jaylen Warren (RB, PIT) | B15: Standalone value + league-winner if Harris-type role opens.
A16: Jalen Coker (WR, CAR) | B16: Cheap target share.
A17: Jaxson Dart (QB, NYG) | B17: Late-round rushing-QB lottery ticket.
A19: INJURY WATCH (draftable — confirm status draft day)
A20: Ashton Jeanty (RB, LV) | B20: Ankle — Wk1 uncertain; ADP slid ~15 to 19. Real discount if it drops him to your R2 turn.
A21: Puka Nacua (WR, LAR) | B21: Groin — expected Week 1.
A22: Malik Nabers (WR, NYG) | B22: Knee — expected Week 1.
A23: Breece Hall (RB, NYJ) | B23: Groin, out 2-3 weeks — expected Week 1.
A24: Emeka Egbuka (WR, TB) | B24: Toe — day-to-day, monitor.
A25: Jeremiyah Love (RB, ARI) | B25: High-ankle sprain — expected Week 1.
A26: George Kittle (TE, SF) | B26: Achilles — activated off PUP, expected Week 1.
A27: Patrick Mahomes (QB, KC) | B27: Knee — playing, but rushing upside may dip.
A29: FADES / AVOID (hurt too much or priced too high)
A30: Ricky Pearsall (WR, SF) | B30: OUT for 2026 (PCL surgery). Do not draft.
A31: Jayden Higgins (WR, HOU) | B31: OUT for 2026 (ACL). Do not draft.
A32: Jordyn Tyson (WR, NO) | B32: Hamstring — ~2 months / likely IR. Stash only, don't reach.
A33: Kyle Monangai (RB, CHI) | B33: Knee — multi-week; falling value.
A34: Cam Skattebo (RB, NYG) | B34: Flagged as one of the riskiest top-50 picks.
A36: HANDCUFFS (grab late to protect your studs)
A37: RJ Harvey (DEN) | B37: Behind J.K. Dobbins.
A38: Jonathon Brooks (CAR) | B38: Committee with Chuba Hubbard.
A39: Rico Dowdle (PIT) | B39: Behind Jaylen Warren.
A40: Kenny Gainwell (TB) | B40: Behind Bucky Irving.
A41: Rhamondre Stevenson / T. Henderson (NE) | B41: Whichever you don't roster.

Sheet FAAB ($100)
A1: FAAB — $100 SEASON FREE-AGENT BUDGET (in-season waiver bidding)
A2: This is your in-season pot for bidding on free agents — separate from the draft. How to make it last:
A4: Save it for RBs | B4: Most FAAB league-winners are backup RBs who fall into a starting job (injury or benching). Spend your biggest bids there, not on WRs.
A5: Be aggressive early (Wks 1-4) | B5: This is when breakout RB/WRs first surface and roles shift. Pounce on real opportunity — but don't empty the tank.
A6: Cap any single bid | B6: Rarely go over ~$30-40 on one player unless it's a clear league-winner (a true every-down bell-cow RB).
A7: Keep dry powder | B7: Hold ~$25-30 into the fantasy playoff push (Wks 12-14) for an injury replacement or a great matchup streamer.
A8: Win ties with odd bids | B8: Bid $17 or $23, never round numbers — you edge out everyone parked on $15 / $20.
A9: Stream defenses cheap | B9: No kicker in this league. Defenses and one-week fill-ins are $0-2 bids — stream the matchup, never pay up.
A10: Don't panic Week 1 | B10: Let roles settle a week or two before spending on preseason hype or one big game.
